Workbook
Name lista_aforadores: LISTAS!$A$1:$A$1000
Name lista_clientes: LISTAS!$B$1:$B$1000
Name lista_tipo_gasto: LISTAS!$D$1:$D$1000
Name OsTransferencias: LISTAS!$E$2:$E$1000
Name lista_bancos: LISTAS!$C$1:$C$1000
Name ListaOS: 'BASE OS'!$A$2:$A$1000
Name lista_tipo_factura: LISTAS!$F$2:$F$1000
Name lista_tipo_pago: LISTAS!$G$2:$G$1000

Sheet PANEL PRINCIPAL
A1: PANEL PRINCIPAL DE GESTIÓN OS
A3: GENERADOR DE OS
A4: Próxima OS | F4: =CONCATENATE(TEXT(COUNTIF('BASE OS'!A:A,"*-"&TEXT(YEAR(TODAY()),"0000"))+1,"000"),"-",TEXT(YEAR(TODAY()),"0000")) -> 001-2025
A6: RESUMEN DEL DÍA
A7: Os Pendientes | F7: =COUNTIF('BASE OS'!I:I,"No") -> 5
A8: Transferencias Hoy | F8: =COUNTIF('BASE TRANSFERENCIAS'!K:K,TODAY()) -> 0
A10: =IFERROR(__xludf.DUMMYFUNCTION("QUERY( 'BASE OS'!A:I, ""SELECT A, B, E, F, G, I ORDER BY A DESC LIMIT 5"", 1 )"),"OS") -> OS | B10: =IFERROR(__xludf.DUMMYFUNCTION("""COMPUTED_VALUE"""),"CLIENTE") -> CLIENTE | C10: =IFERROR(__xludf.DUMMYFUNCTION("""COMPUTED_VALUE"""),"AFORADOR") -> AFORADOR | D10: =IFERROR(__xludf.DUMMYFUNCTION("""COMPUTED_VALUE"""),"REFERENCIA / BL") -> REFERENCIA / BL | E10: =IFERROR(__xludf.DUMMYFUNCTION("""COMPUTED_VALUE"""),"FECHA") -> FECHA | F10: =IFERROR(__xludf.DUMMYFUNCTION("""COMPUTED_VALUE"""),"FACTURADO") -> FACTURADO
A11: =IFERROR(__xludf.DUMMYFUNCTION("""COMPUTED_VALUE"""),"008-2024") -> 008-2024 | B11: =IFERROR(__xludf.DUMMYFUNCTION("""COMPUTED_VALUE"""),"QUIMICA INDUSTRIAL") -> QUIMICA INDUSTRIAL | C11: =IFERROR(__xludf.DUMMYFUNCTION("""COMPUTED_VALUE"""),"ROBERTO") -> ROBERTO | D11: =IFERROR(__xludf.DUMMYFUNCTION("""COMPUTED_VALUE"""),"146-28394") -> 146-28394 | E11: =IFERROR(__xludf.DUMMYFUNCTION("""COMPUTED_VALUE"""),45609.0) -> 45609 | F11: =IFERROR(__xludf.DUMMYFUNCTION("""COMPUTED_VALUE"""),"No") -> No
A12: =IFERROR(__xludf.DUMMYFUNCTION("""COMPUTED_VALUE"""),"007-2024") -> 007-2024 | B12: =IFERROR(__xludf.DUMMYFUNCTION("""COMPUTED_VALUE"""),"AISAL") -> AISAL | C12: =IFERROR(__xludf.DUMMYFUNCTION("""COMPUTED_VALUE"""),"MARÍA JOSE") -> MARÍA JOSE | D12: =IFERROR(__xludf.DUMMYFUNCTION("""COMPUTED_VALUE"""),"146-34599") -> 146-34599 | E12: =IFERROR(__xludf.DUMMYFUNCTION("""COMPUTED_VALUE"""),45608.0) -> 45608 | F12: =IFERROR(__xludf.DUMMYFUNCTION("""COMPUTED_VALUE"""),"No") -> No
A13: =IFERROR(__xludf.DUMMYFUNCTION("""COMPUTED_VALUE"""),"006-2024") -> 006-2024 | B13: =IFERROR(__xludf.DUMMYFUNCTION("""COMPUTED_VALUE"""),"GEVI") -> GEVI | C13: =IFERROR(__xludf.DUMMYFUNCTION("""COMPUTED_VALUE"""),"GLENDA CAÑAS") -> GLENDA CAÑAS | D13: =IFERROR(__xludf.DUMMYFUNCTION("""COMPUTED_VALUE"""),"146-34251") -> 146-34251 | E13: =IFERROR(__xludf.DUMMYFUNCTION("""COMPUTED_VALUE"""),45607.0) -> 45607 | F13: =IFERROR(__xludf.DUMMYFUNCTION("""COMPUTED_VALUE"""),"No") -> No
A14: =IFERROR(__xludf.DUMMYFUNCTION("""COMPUTED_VALUE"""),"005-2024") -> 005-2024 | B14: =IFERROR(__xludf.DUMMYFUNCTION("""COMPUTED_VALUE"""),"AISAL") -> AISAL | C14: =IFERROR(__xludf.DUMMYFUNCTION("""COMPUTED_VALUE"""),"MARÍA JOSE") -> MARÍA JOSE | D14: =IFERROR(__xludf.DUMMYFUNCTION("""COMPUTED_VALUE"""),"146-34223") -> 146-34223 | E14: =IFERROR(__xludf.DUMMYFUNCTION("""COMPUTED_VALUE"""),45607.0) -> 45607 | F14: =IFERROR(__xludf.DUMMYFUNCTION("""COMPUTED_VALUE"""),"No") -> No
A15: =IFERROR(__xludf.DUMMYFUNCTION("""COMPUTED_VALUE"""),"004-2024") -> 004-2024 | B15: =IFERROR(__xludf.DUMMYFUNCTION("""COMPUTED_VALUE"""),"DIGICEL") -> DIGICEL | C15: =IFERROR(__xludf.DUMMYFUNCTION("""COMPUTED_VALUE"""),"ROBERTO") -> ROBERTO | D15: =IFERROR(__xludf.DUMMYFUNCTION("""COMPUTED_VALUE"""),"146-29934") -> 146-29934 | E15: =IFERROR(__xludf.DUMMYFUNCTION("""COMPUTED_VALUE"""),45606.0) -> 45606 | F15: =IFERROR(__xludf.DUMMYFUNCTION("""COMPUTED_VALUE"""),"No") -> No

Sheet REGISTRO OS
B1: REGISTRO DE NUEVA OS
C3: Número OS | E3: =CONCATENATE( TEXT( COUNTIF( 'BASE OS'!A:A, "*-"&TEXT(YEAR(TODAY()),"0000") )+1, "000" ), "-", TEXT(YEAR(TODAY()),"0000") ) -> 001-2025 | G3: Vista Previa
C5: Cliente | E5: TRANSTAINER | G5: OS: | H5: =E3 -> 001-2025
G6: Cliente: | H6: =E5 -> TRANSTAINER
C7: Sub - Cliente | E7: N/A | G7: Sub - Cliente: | H7: =E7 -> N/A
G8: DUCA / Servicio: | H8: =E9 -> 4-16283
C9: DUCA / Servicio | E9: 4-16283 | G9: Aforador: | H9: =E11 -> GLENDA CAÑAS
G10: Referencia / BL: | H10: =E13 -> 146-25382
C11: Aforador | E11: GLENDA CAÑAS | G11: Fecha: | H11: =E15 -> 45621
C13: Referencia / BL | E13: 146-25382
C15: Fecha | E15: 45621

Sheet BASE OS
A1: OS | B1: CLIENTE | C1: SUB CLIENTE | D1: DUCA - SERVICIO | E1: AFORADOR | F1: REFERENCIA / BL | G1: FECHA | H1: MES | I1: FACTURADO
A2: 001-2024 | B2: PANADERIA SINAI | C2: N/A | D2: 4-38493 | E2: ADELAYDA | F2: 146-28394 | G2: 45606 | H2: NOVIEMBRE | I2: Sí
A3: 002-2024 | B3: PINTO Y COMPANIA | C3: N/A | D3: 4-28394 | E3: ADELAYDA | F3: 146-28394 | G3: 45606 | H3: NOVIEMBRE | I3: Sí
A4: 003-2024 | B4: DIVACO | C4: N/A | D4: 4-23934 | E4: GLENDA CAÑAS | F4: 146-33843 | G4: 45606 | H4: NOVIEMBRE | I4: Sí
A5: 004-2024 | B5: DIGICEL | C5: N/A | D5: 4-29394 | E5: ROBERTO | F5: 146-29934 | G5: 45606 | H5: NOVIEMBRE | I5: No
A6: 005-2024 | B6: AISAL | C6: N/A | D6: 4-22567 | E6: MARÍA JOSE | F6: 146-34223 | G6: 45607 | H6: NOVIEMBRE | I6: No
A7: 006-2024 | B7: GEVI | C7: N/A | D7: 4-35685 | E7: GLENDA CAÑAS | F7: 146-34251 | G7: 45607 | H7: NOVIEMBRE | I7: No
A8: 007-2024 | B8: AISAL | C8: N/A | D8: 4-35969 | E8: MARÍA JOSE | F8: 146-34599 | G8: 45608 | H8: NOVIEMBRE | I8: No
A9: 008-2024 | B9: QUIMICA INDUSTRIAL | C9: N/A | D9: 4-38492 | E9: ROBERTO | F9: 146-28394 | G9: 45609 | H9: NOVIEMBRE | I9: No | J9: TRUE | K9: Proteger registro

Sheet REGISTRO TRANSFERENCIAS
B1: REGISTRO DE TRANSFERENCIAS
C3: Número OS
C5: Cliente
C7: A Nombre De
C9: Detalle
C11: Monto
C13: Solicitado Por
C15: Banco
C17: Tipo de Gasto
C19: Fecha

Sheet BASE TRANSFERENCIAS
A1: OS | B1: CLIENTE | C1: SUB CLIENTE | D1: A NOMBRE DE | E1: DETALLE | F1: CCF | G1: MONTO | H1: SOLICITADO POR | I1: BANCO | J1: TIPO | K1: FECHA | L1: MES
A2: 001-2024 | B2: PANADERIA SINAI | C2: N/A | D2: M.H | E2: IMPUESTOS | G2: 33.284 | H2: MARÍA JOSE | I2: AGRICOLA | J2: CARGOS A CLIENTES | K2: 45606 | L2: =IF(ISBLANK(K2),"",UPPER(TEXT(K2,"MMMM"))) -> NOVIEMBRE
A3: 006-2024 | B3: GEVI | C3: N/A | D3: M.H | E3: IMPUESTOS | G3: 125.588 | H3: GLENDA CAÑAS | I3: AGRICOLA | J3: CARGOS A CLIENTES | K3: 45608 | L3: =IF(ISBLANK(K3),"",UPPER(TEXT(K3,"MMMM"))) -> NOVIEMBRE
A4: 008-2024 | B4: QUIMICA INDUSTRIAL | C4: N/A | D4: M.H | E4: IMPUESTOS | G4: 65.68 | H4: ADELAYDA | I4: AGRICOLA | J4: CARGOS A CLIENTES | K4: 45609 | L4: =IF(ISBLANK(K4),"",UPPER(TEXT(K4,"MMMM"))) -> NOVIEMBRE
A5: 008-2024 | B5: QUIMICA INDUSTRIAL | C5: N/A | D5: CEPA | E5: ALMACENAJE | G5: 25.99 | H5: ADELAYDA | I5: AGRICOLA | J5: CARGOS A CLIENTES | K5: 45609 | L5: =IF(ISBLANK(K5),"",UPPER(TEXT(K5,"MMMM"))) -> NOVIEMBRE | M5: TRUE | N5: Proteger registro
L6: =IF(ISBLANK(K6),"",UPPER(TEXT(K6,"MMMM")))
L7: =IF(ISBLANK(K7),"",UPPER(TEXT(K7,"MMMM")))
L8: =IF(ISBLANK(K8),"",UPPER(TEXT(K8,"MMMM")))
L9: =IF(ISBLANK(K9),"",UPPER(TEXT(K9,"MMMM")))
L10: =IF(ISBLANK(K10),"",UPPER(TEXT(K10,"MMMM")))
L11: =IF(ISBLANK(K11),"",UPPER(TEXT(K11,"MMMM")))
L12: =IF(ISBLANK(K12),"",UPPER(TEXT(K12,"MMMM")))
L13: =IF(ISBLANK(K13),"",UPPER(TEXT(K13,"MMMM")))
L14: =IF(ISBLANK(K14),"",UPPER(TEXT(K14,"MMMM")))
L15: =IF(ISBLANK(K15),"",UPPER(TEXT(K15,"MMMM")))
L16: =IF(ISBLANK(K16),"",UPPER(TEXT(K16,"MMMM")))
L17: =IF(ISBLANK(K17),"",UPPER(TEXT(K17,"MMMM")))
... L1001: =IF(ISBLANK(K1001),"",UPPER(TEXT(K1001,"MMMM")))

Sheet CALCULO COBROS
A1: CALCULO DE COBROS
A3: Número OS | D3: Cliente | G3: RESUMEN DE COBRO
D4: =IFERROR(VLOOKUP($A$4,'BASE OS'!A:B,2,FALSE),"") | G4: Total Servicios (IVA incluido) | H4: =SUM(F15:F24)+((SUM(F15:F24)*13%)) -> 0
G5: Gastos a Terceros: | H5: =SUM(E30:E39) -> 0
A6: Subcliente | D6: DUCA | G6: Total a pagar: | H6: =SUM(H4:H5) -> 0
A7: =IFERROR(VLOOKUP($A$4,'BASE OS'!A:C,3,FALSE),"") | D7: =IFERROR(VLOOKUP($A$4,'BASE OS'!A:D,4,FALSE),"")
A9: Referencia/BL | D9: Fecha
A10: =IFERROR(VLOOKUP($A$4,'BASE OS'!A:F,6,FALSE),"") | D10: =IFERROR(VLOOKUP($A$4,'BASE OS'!A:G,7,FALSE),"")
A13: SERVICIOS PRESTADOS
A14: SI / NO | B14: SERVICIO | D14: PRECIO BASE | E14: AJUSTE | F14: PRECIO FINAL | G14: NOTAS
D15: =IF(AND(LEN(B15)>0,LEN($D$4)>0),IFERROR(VLOOKUP(B15,TARIFARIO!$I$2:$J$10000,2,FALSE),"Servicio no encontrado"),"") | F15: =IFERROR(IF(AND(A15=TRUE,D15<>""),D15+IF(E15<>"",E15,0),""),"")
D16: =IF(AND(LEN(B16)>0,LEN($D$4)>0),IFERROR(VLOOKUP(B16,TARIFARIO!$I$2:$J$10000,2,FALSE),"Servicio no encontrado"),"") | F16: =IFERROR(IF(AND(A16=TRUE,D16<>""),D16+IF(E16<>"",E16,0),""),"")
D17: =IF(AND(LEN(B17)>0,LEN($D$4)>0),IFERROR(VLOOKUP(B17,TARIFARIO!$I$2:$J$10000,2,FALSE),"Servicio no encontrado"),"") | F17: =IFERROR(IF(AND(A17=TRUE,D17<>""),D17+IF(E17<>"",E17,0),""),"")
D18: =IF(AND(LEN(B18)>0,LEN($D$4)>0),IFERROR(VLOOKUP(B18,TARIFARIO!$I$2:$J$10000,2,FALSE),"Servicio no encontrado"),"") | F18: =IFERROR(IF(AND(A18=TRUE,D18<>""),D18+IF(E18<>"",E18,0),""),"")
D19: =IF(AND(LEN(B19)>0,LEN($D$4)>0),IFERROR(VLOOKUP(B19,TARIFARIO!$I$2:$J$10000,2,FALSE),"Servicio no encontrado"),"") | F19: =IFERROR(IF(AND(A19=TRUE,D19<>""),D19+IF(E19<>"",E19,0),""),"")
D20: =IF(AND(LEN(B20)>0,LEN($D$4)>0),IFERROR(VLOOKUP(B20,TARIFARIO!$I$2:$J$10000,2,FALSE),"Servicio no encontrado"),"") | F20: =IFERROR(IF(AND(A20=TRUE,D20<>""),D20+IF(E20<>"",E20,0),""),"")
D21: =IF(AND(LEN(B21)>0,LEN($D$4)>0),IFERROR(VLOOKUP(B21,TARIFARIO!$I$2:$J$10000,2,FALSE),"Servicio no encontrado"),"")
D22: =IF(AND(LEN(B22)>0,LEN($D$4)>0),IFERROR(VLOOKUP(B22,TARIFARIO!$I$2:$J$10000,2,FALSE),"Servicio no encontrado"),"")
D23: =IF(AND(LEN(B23)>0,LEN($D$4)>0),IFERROR(VLOOKUP(B23,TARIFARIO!$I$2:$J$10000,2,FALSE),"Servicio no encontrado"),"")
D24: =IF(AND(LEN(B24)>0,LEN($D$4)>0),IFERROR(VLOOKUP(B24,TARIFARIO!$I$2:$J$10000,2,FALSE),"Servicio no encontrado"),"") | F24: =IFERROR(IF(AND(A24=TRUE,D24<>""),D24+IF(E24<>"",E24,0),""),"")
A25: TOTALES | D25: =IF(SUM(D15:D24)=0,"",SUM(D15:D24)) | E25: =IF(SUM(E15:E24)=0,"",SUM(E15:E24)) | F25: =IF(SUM(F15:F24)=0,"",SUM(F15:F24))
A28: TRANSFERENCIAS ASOCIADAS
A29: =IFERROR(__xludf.DUMMYFUNCTION("QUERY('BASE TRANSFERENCIAS'!A:L,""SELECT I,D,E,F,G,H WHERE A= '""&$A$4&""' ORDER BY I DESC"",1)"),"#REF!") -> #REF!
A40: TOTALES | E40: =SUM(E30:E39) -> 0

Sheet HISTÓRICO COBROS
A1: HISTORICO DE COBROS
A2: OS | B2: FECHA | C2: CLIENTE | D2: SERVICIOS | E2: TOTAL SERVICIOS | F2: TOTAL GASTOS A TERCEROS | G2: TOTAL COBRADO | H2: NOTAS
A3: 001-2024 | B3: 45606 | C3: PANADERIA SINAI | D3: ASESORÍA Y GESTIÓN ADUANAL - OTRO | E3: 129.95 | F3: 33.284 | G3: 163.234
A4: 002-2024 | B4: 45606 | C4: PINTO Y COMPANIA | D4: ASESORÍA Y GESTIÓN ADUANAL - OTRO | E4: 67.8 | F4: 0 | G4: 67.8
A5: 003-2024 | B5: 45606 | C5: DIVACO | D5: ASESORIA Y GESTION ADUANERA - ACAJUTLA | E5: 79.1 | F5: 0 | G5: 79.1
A6: 004-2024 | B6: 45606 | C6: DIGICEL | D6: ASESORIA Y GESTION ADUANERA ALMACENADORA - AEROPUERTO, TRANSPORTE LOCAL DHL - DIGICEL | E6: 113 | F6: 0 | G6: 113
A7: 008-2024 | B7: 45609 | C7: QUIMICA INDUSTRIAL | D7: ASESORÍA Y GESTIÓN ADUANAL - OTRO, TRANSPORTE LOCAL - OTRO | E7: 209.05 | F7: 91.67 | G7: 300.72

Sheet CXC
A1: OS | B1: CLIENTE | C1: Fecha de Factura | D1: TIPO | E1: Numero | F1: Fecha de vencimiento | G1: Nº Quedan | H1: Facturacion | I1: Gastos a tercero | J1: Total de Facturación | K1: Abono o Pago Facturación | L1: Abono o Pago Prestamos | M1: CxC | N1: CXC Facturación | O1: CXC Prestamos | P1: Fecha de Abono | Q1: Tipo de pago | R1: Estado | S1: Días Vencidos | T1: DUCA | U1: PO | V1: Observaciones | W1: Mes | X1: No. Mes | Y1: Año
A2: 001-2024 | B2: =IF(A2="","",VLOOKUP(A2,'BASE OS'!$A$2:$I1000,2,FALSE)) -> PANADERIA SINAI | C2: 45608 | D2: DTE | H2: 129.95 | I2: 33.284 | J2: =H2+I2 -> 163.234 | M2: =J2-K2-L2 -> 163.234 | Q2: TRANSFERENCIA | R2: PENDIENTE | T2: =IF(A2="","",VLOOKUP(A2,'BASE OS'!$A$2:$I1000,4,FALSE)) -> 4-38493 | W2: =IF(ISBLANK(C2),"",UPPER(TEXT(C2,"MMMM"))) -> NOVIEMBRE | X2: =IF(C2="","",MONTH(C2)) -> 11 | Y2: =IF(C2="","", YEAR(C2)) -> 2024
A3: 002-2024 | B3: =IF(A3="","",VLOOKUP(A3,'BASE OS'!$A$2:$I1000,2,FALSE)) -> PINTO Y COMPANIA | C3: 45608 | D3: DTE | H3: 67.8 | I3: 0 | J3: =H3+I3 -> 67.8 | M3: =J3-K3-L3 -> 67.8 | Q3: TRANSFERENCIA | R3: PENDIENTE | T3: =IF(A3="","",VLOOKUP(A3,'BASE OS'!$A$2:$I1000,4,FALSE)) -> 4-28394 | W3: =IF(ISBLANK(C3),"",UPPER(TEXT(C3,"MMMM"))) -> NOVIEMBRE | X3: =IF(C3="","",MONTH(C3)) -> 11 | Y3: =IF(C3="","", YEAR(C3)) -> 2024
A4: 003-2024 | B4: =IF(A4="","",VLOOKUP(A4,'BASE OS'!$A$2:$I1000,2,FALSE)) -> DIVACO | C4: 45608 | D4: DTE | H4: 79.1 | I4: 0 | J4: =H4+I4 -> 79.1 | M4: =J4-K4-L4 -> 79.1 | Q4: TRANSFERENCIA | R4: PENDIENTE | T4: =IF(A4="","",VLOOKUP(A4,'BASE OS'!$A$2:$I1000,4,FALSE)) -> 4-23934 | W4: =IF(ISBLANK(C4),"",UPPER(TEXT(C4,"MMMM"))) -> NOVIEMBRE | X4: =IF(C4="","",MONTH(C4)) -> 11 | Y4: =IF(C4="","", YEAR(C4)) -> 2024
A5: 004-2024 | B5: =IF(A5="","",VLOOKUP(A5,'BASE OS'!$A$2:$I1000,2,FALSE)) -> DIGICEL | C5: 45609 | D5: DTE | H5: 113 | I5: 0 | J5: =H5+I5 -> 113 | M5: =J5-K5-L5 -> 113 | Q5: TRANSFERENCIA | R5: PENDIENTE | T5: =IF(A5="","",VLOOKUP(A5,'BASE OS'!$A$2:$I1000,4,FALSE)) -> 4-29394 | W5: =IF(ISBLANK(C5),"",UPPER(TEXT(C5,"MMMM"))) -> NOVIEMBRE | X5: =IF(C5="","",MONTH(C5)) -> 11 | Y5: =IF(C5="","", YEAR(C5)) -> 2024
A6: 005-2024 | B6: =IF(A6="","",VLOOKUP(A6,'BASE OS'!$A$2:$I1000,2,FALSE)) -> AISAL | C6: 45609 | D6: DTE | H6: 50.59 | I6: 53.55 | J6: =H6+I6 -> 104.14 | M6: =J6-K6-L6 -> 104.14 | Q6: TRANSFERENCIA | R6: PENDIENTE | T6: =IF(A6="","",VLOOKUP(A6,'BASE OS'!$A$2:$I1000,4,FALSE)) -> 4-22567 | W6: =IF(ISBLANK(C6),"",UPPER(TEXT(C6,"MMMM"))) -> NOVIEMBRE | X6: =IF(C6="","",MONTH(C6)) -> 11 | Y6: =IF(C6="","", YEAR(C6)) -> 2024
A7: 006-2024 | B7: =IF(A7="","",VLOOKUP(A7,'BASE OS'!$A$2:$I1000,2,FALSE)) -> GEVI | C7: 45609 | D7: DTE | H7: 25.1 | I7: 30.55 | J7: =H7+I7 -> 55.65 | M7: =J7-K7-L7 -> 55.65 | Q7: TRANSFERENCIA | R7: PENDIENTE | T7: =IF(A7="","",VLOOKUP(A7,'BASE OS'!$A$2:$I1000,4,FALSE)) -> 4-35685 | W7: =IF(ISBLANK(C7),"",UPPER(TEXT(C7,"MMMM"))) -> NOVIEMBRE | X7: =IF(C7="","",MONTH(C7)) -> 11 | Y7: =IF(C7="","", YEAR(C7)) -> 2024
A8: 007-2024 | B8: =IF(A8="","",VLOOKUP(A8,'BASE OS'!$A$2:$I1000,2,FALSE)) -> AISAL | C8: 45609 | D8: DTE | H8: 50.1 | I8: 0 | J8: =H8+I8 -> 50.1 | M8: =J8-K8-L8 -> 50.1 | Q8: TRANSFERENCIA | R8: PENDIENTE | T8: =IF(A8="","",VLOOKUP(A8,'BASE OS'!$A$2:$I1000,4,FALSE)) -> 4-35969 | W8: =IF(ISBLANK(C8),"",UPPER(TEXT(C8,"MMMM"))) -> NOVIEMBRE | X8: =IF(C8="","",MONTH(C8)) -> 11 | Y8: =IF(C8="","", YEAR(C8)) -> 2024
A9: 008-2024 | B9: =IF(A9="","",VLOOKUP(A9,'BASE OS'!$A$2:$I1000,2,FALSE)) -> QUIMICA INDUSTRIAL | C9: 45609 | D9: DTE | H9: 209.05 | I9: 91.67 | J9: =H9+I9 -> 300.72 | M9: =J9-K9-L9 -> 300.72 | Q9: TRANSFERENCIA | R9: PENDIENTE | T9: =IF(A9="","",VLOOKUP(A9,'BASE OS'!$A$2:$I1000,4,FALSE)) -> 4-38492 | W9: =IF(ISBLANK(C9),"",UPPER(TEXT(C9,"MMMM"))) -> NOVIEMBRE | X9: =IF(C9="","",MONTH(C9)) -> 11 | Y9: =IF(C9="","", YEAR(C9)) -> 2024
B10: =IF(A10="","",VLOOKUP(A10,'BASE OS'!$A$2:$I1000,2,FALSE)) | J10: =H10+I10 -> 0 | M10: =J10-K10-L10 -> 0 | T10: =IF(A10="","",VLOOKUP(A10,'BASE OS'!$A$2:$I1000,4,FALSE)) | W10: =IF(ISBLANK(C10),"",UPPER(TEXT(C10,"MMMM"))) | X10: =IF(C10="","",MONTH(C10)) | Y10: =IF(C10="","", YEAR(C10))
B11: =IF(A11="","",VLOOKUP(A11,'BASE OS'!$A$2:$I1000,2,FALSE)) | J11: =H11+I11 -> 0 | M11: =J11-K11-L11 -> 0 | T11: =IF(A11="","",VLOOKUP(A11,'BASE OS'!$A$2:$I1000,4,FALSE)) | W11: =IF(ISBLANK(C11),"",UPPER(TEXT(C11,"MMMM"))) | X11: =IF(C11="","",MONTH(C11)) | Y11: =IF(C11="","", YEAR(C11))
B12: =IF(A12="","",VLOOKUP(A12,'BASE OS'!$A$2:$I1000,2,FALSE)) | J12: =H12+I12 -> 0 | M12: =J12-K12-L12 -> 0 | T12: =IF(A12="","",VLOOKUP(A12,'BASE OS'!$A$2:$I1000,4,FALSE)) | W12: =IF(ISBLANK(C12),"",UPPER(TEXT(C12,"MMMM"))) | X12: =IF(C12="","",MONTH(C12)) | Y12: =IF(C12="","", YEAR(C12))
B13: =IF(A13="","",VLOOKUP(A13,'BASE OS'!$A$2:$I1000,2,FALSE)) | J13: =H13+I13 -> 0 | M13: =J13-K13-L13 -> 0 | T13: =IF(A13="","",VLOOKUP(A13,'BASE OS'!$A$2:$I1000,4,FALSE)) | W13: =IF(ISBLANK(C13),"",UPPER(TEXT(C13,"MMMM"))) | X13: =IF(C13="","",MONTH(C13)) | Y13: =IF(C13="","", YEAR(C13))
B14: =IF(A14="","",VLOOKUP(A14,'BASE OS'!$A$2:$I1000,2,FALSE)) | J14: =H14+I14 -> 0 | M14: =J14-K14-L14 -> 0 | T14: =IF(A14="","",VLOOKUP(A14,'BASE OS'!$A$2:$I1000,4,FALSE)) | W14: =IF(ISBLANK(C14),"",UPPER(TEXT(C14,"MMMM"))) | X14: =IF(C14="","",MONTH(C14)) | Y14: =IF(C14="","", YEAR(C14))
B15: =IF(A15="","",VLOOKUP(A15,'BASE OS'!$A$2:$I1000,2,FALSE)) | J15: =H15+I15 -> 0 | M15: =J15-K15-L15 -> 0 | T15: =IF(A15="","",VLOOKUP(A15,'BASE OS'!$A$2:$I1000,4,FALSE)) | W15: =IF(ISBLANK(C15),"",UPPER(TEXT(C15,"MMMM"))) | X15: =IF(C15="","",MONTH(C15)) | Y15: =IF(C15="","", YEAR(C15))
B16: =IF(A16="","",VLOOKUP(A16,'BASE OS'!$A$2:$I1000,2,FALSE)) | J16: =H16+I16 -> 0 | M16: =J16-K16-L16 -> 0 | T16: =IF(A16="","",VLOOKUP(A16,'BASE OS'!$A$2:$I1000,4,FALSE)) | W16: =IF(ISBLANK(C16),"",UPPER(TEXT(C16,"MMMM"))) | X16: =IF(C16="","",MONTH(C16)) | Y16: =IF(C16="","", YEAR(C16))
B17: =IF(A17="","",VLOOKUP(A17,'BASE OS'!$A$2:$I1000,2,FALSE)) | J17: =H17+I17 -> 0 | M17: =J17-K17-L17 -> 0 | T17: =IF(A17="","",VLOOKUP(A17,'BASE OS'!$A$2:$I1000,4,FALSE)) | W17: =IF(ISBLANK(C17),"",UPPER(TEXT(C17,"MMMM"))) | X17: =IF(C17="","",MONTH(C17)) | Y17: =IF(C17="","", YEAR(C17))
B18: =IF(A18="","",VLOOKUP(A18,'BASE OS'!$A$2:$I1000,2,FALSE)) | J18: =H18+I18 -> 0 | M18: =J18-K18-L18 -> 0 | T18: =IF(A18="","",VLOOKUP(A18,'BASE OS'!$A$2:$I1000,4,FALSE)) | W18: =IF(ISBLANK(C18),"",UPPER(TEXT(C18,"MMMM"))) | X18: =IF(C18="","",MONTH(C18)) | Y18: =IF(C18="","", YEAR(C18))
B19: =IF(A19="","",VLOOKUP(A19,'BASE OS'!$A$2:$I1000,2,FALSE)) | J19: =H19+I19 -> 0 | M19: =J19-K19-L19 -> 0 | T19: =IF(A19="","",VLOOKUP(A19,'BASE OS'!$A$2:$I1000,4,FALSE)) | W19: =IF(ISBLANK(C19),"",UPPER(TEXT(C19,"MMMM"))) | X19: =IF(C19="","",MONTH(C19)) | Y19: =IF(C19="","", YEAR(C19))
B20: =IF(A20="","",VLOOKUP(A20,'BASE OS'!$A$2:$I1000,2,FALSE)) | J20: =H20+I20 -> 0 | M20: =J20-K20-L20 -> 0 | T20: =IF(A20="","",VLOOKUP(A20,'BASE OS'!$A$2:$I1000,4,FALSE)) | W20: =IF(ISBLANK(C20),"",UPPER(TEXT(C20,"MMMM"))) | X20: =IF(C20="","",MONTH(C20)) | Y20: =IF(C20="","", YEAR(C20))
B21: =IF(A21="","",VLOOKUP(A21,'BASE OS'!$A$2:$I1000,2,FALSE)) | J21: =H21+I21 -> 0 | M21: =J21-K21-L21 -> 0 | T21: =IF(A21="","",VLOOKUP(A21,'BASE OS'!$A$2:$I1000,4,FALSE)) | W21: =IF(ISBLANK(C21),"",UPPER(TEXT(C21,"MMMM"))) | X21: =IF(C21="","",MONTH(C21)) | Y21: =IF(C21="","", YEAR(C21))
B22: =IF(A22="","",VLOOKUP(A22,'BASE OS'!$A$2:$I1000,2,FALSE)) | J22: =H22+I22 -> 0 | M22: =J22-K22-L22 -> 0 | T22: =IF(A22="","",VLOOKUP(A22,'BASE OS'!$A$2:$I1000,4,FALSE)) | W22: =IF(ISBLANK(C22),"",UPPER(TEXT(C22,"MMMM"))) | X22: =IF(C22="","",MONTH(C22)) | Y22: =IF(C22="","", YEAR(C22))
B23: =IF(A23="","",VLOOKUP(A23,'BASE OS'!$A$2:$I1000,2,FALSE)) | J23: =H23+I23 -> 0 | M23: =J23-K23-L23 -> 0 | T23: =IF(A23="","",VLOOKUP(A23,'BASE OS'!$A$2:$I1000,4,FALSE)) | W23: =IF(ISBLANK(C23),"",UPPER(TEXT(C23,"MMMM"))) | X23: =IF(C23="","",MONTH(C23)) | Y23: =IF(C23="","", YEAR(C23))
B24: =IF(A24="","",VLOOKUP(A24,'BASE OS'!$A$2:$I1000,2,FALSE)) | J24: =H24+I24 -> 0 | M24: =J24-K24-L24 -> 0 | T24: =IF(A24="","",VLOOKUP(A24,'BASE OS'!$A$2:$I1000,4,FALSE)) | W24: =IF(ISBLANK(C24),"",UPPER(TEXT(C24,"MMMM"))) | X24: =IF(C24="","",MONTH(C24)) | Y24: =IF(C24="","", YEAR(C24))
B25: =IF(A25="","",VLOOKUP(A25,'BASE OS'!$A$2:$I1000,2,FALSE)) | J25: =H25+I25 -> 0 | M25: =J25-K25-L25 -> 0 | T25: =IF(A25="","",VLOOKUP(A25,'BASE OS'!$A$2:$I1000,4,FALSE)) | W25: =IF(ISBLANK(C25),"",UPPER(TEXT(C25,"MMMM"))) | X25: =IF(C25="","",MONTH(C25)) | Y25: =IF(C25="","", YEAR(C25))
B26: =IF(A26="","",VLOOKUP(A26,'BASE OS'!$A$2:$I1000,2,FALSE)) | J26: =H26+I26 -> 0 | M26: =J26-K26-L26 -> 0 | T26: =IF(A26="","",VLOOKUP(A26,'BASE OS'!$A$2:$I1000,4,FALSE)) | W26: =IF(ISBLANK(C26),"",UPPER(TEXT(C26,"MMMM"))) | X26: =IF(C26="","",MONTH(C26)) | Y26: =IF(C26="","", YEAR(C26))
B27: =IF(A27="","",VLOOKUP(A27,'BASE OS'!$A$2:$I1000,2,FALSE)) | J27: =H27+I27 -> 0 | M27: =J27-K27-L27 -> 0 | T27: =IF(A27="","",VLOOKUP(A27,'BASE OS'!$A$2:$I1000,4,FALSE)) | W27: =IF(ISBLANK(C27),"",UPPER(TEXT(C27,"MMMM"))) | X27: =IF(C27="","",MONTH(C27)) | Y27: =IF(C27="","", YEAR(C27))
B28: =IF(A28="","",VLOOKUP(A28,'BASE OS'!$A$2:$I1000,2,FALSE)) | J28: =H28+I28 -> 0 | M28: =J28-K28-L28 -> 0 | T28: =IF(A28="","",VLOOKUP(A28,'BASE OS'!$A$2:$I1000,4,FALSE)) | W28: =IF(ISBLANK(C28),"",UPPER(TEXT(C28,"MMMM"))) | X28: =IF(C28="","",MONTH(C28)) | Y28: =IF(C28="","", YEAR(C28))
B29: =IF(A29="","",VLOOKUP(A29,'BASE OS'!$A$2:$I1000,2,FALSE)) | J29: =H29+I29 -> 0 | M29: =J29-K29-L29 -> 0 | T29: =IF(A29="","",VLOOKUP(A29,'BASE OS'!$A$2:$I1000,4,FALSE)) | W29: =IF(ISBLANK(C29),"",UPPER(TEXT(C29,"MMMM"))) | X29: =IF(C29="","",MONTH(C29)) | Y29: =IF(C29="","", YEAR(C29))
B30: =IF(A30="","",VLOOKUP(A30,'BASE OS'!$A$2:$I1000,2,FALSE)) | J30: =H30+I30 -> 0 | M30: =J30-K30-L30 -> 0 | T30: =IF(A30="","",VLOOKUP(A30,'BASE OS'!$A$2:$I1000,4,FALSE)) | W30: =IF(ISBLANK(C30),"",UPPER(TEXT(C30,"MMMM"))) | X30: =IF(C30="","",MONTH(C30)) | Y30: =IF(C30="","", YEAR(C30))
B31: =IF(A31="","",VLOOKUP(A31,'BASE OS'!$A$2:$I1000,2,FALSE)) | J31: =H31+I31 -> 0 | M31: =J31-K31-L31 -> 0 | T31: =IF(A31="","",VLOOKUP(A31,'BASE OS'!$A$2:$I1000,4,FALSE)) | W31: =IF(ISBLANK(C31),"",UPPER(TEXT(C31,"MMMM"))) | X31: =IF(C31="","",MONTH(C31)) | Y31: =IF(C31="","", YEAR(C31))
B32: =IF(A32="","",VLOOKUP(A32,'BASE OS'!$A$2:$I1000,2,FALSE)) | J32: =H32+I32 -> 0 | M32: =J32-K32-L32 -> 0 | T32: =IF(A32="","",VLOOKUP(A32,'BASE OS'!$A$2:$I1000,4,FALSE)) | W32: =IF(ISBLANK(C32),"",UPPER(TEXT(C32,"MMMM"))) | X32: =IF(C32="","",MONTH(C32)) | Y32: =IF(C32="","", YEAR(C32))
B33: =IF(A33="","",VLOOKUP(A33,'BASE OS'!$A$2:$I1000,2,FALSE)) | J33: =H33+I33 -> 0 | M33: =J33-K33-L33 -> 0 | T33: =IF(A33="","",VLOOKUP(A33,'BASE OS'!$A$2:$I1000,4,FALSE)) | W33: =IF(ISBLANK(C33),"",UPPER(TEXT(C33,"MMMM"))) | X33: =IF(C33="","",MONTH(C33)) | Y33: =IF(C33="","", YEAR(C33))
B34: =IF(A34="","",VLOOKUP(A34,'BASE OS'!$A$2:$I1000,2,FALSE)) | J34: =H34+I34 -> 0 | M34: =J34-K34-L34 -> 0 | T34: =IF(A34="","",VLOOKUP(A34,'BASE OS'!$A$2:$I1000,4,FALSE)) | W34: =IF(ISBLANK(C34),"",UPPER(TEXT(C34,"MMMM"))) | X34: =IF(C34="","",MONTH(C34)) | Y34: =IF(C34="","", YEAR(C34))
B35: =IF(A35="","",VLOOKUP(A35,'BASE OS'!$A$2:$I1000,2,FALSE)) | J35: =H35+I35 -> 0 | M35: =J35-K35-L35 -> 0 | T35: =IF(A35="","",VLOOKUP(A35,'BASE OS'!$A$2:$I1000,4,FALSE)) | W35: =IF(ISBLANK(C35),"",UPPER(TEXT(C35,"MMMM"))) | X35: =IF(C35="","",MONTH(C35)) | Y35: =IF(C35="","", YEAR(C35))
B36: =IF(A36="","",VLOOKUP(A36,'BASE OS'!$A$2:$I1000,2,FALSE)) | J36: =H36+I36 -> 0 | M36: =J36-K36-L36 -> 0 | T36: =IF(A36="","",VLOOKUP(A36,'BASE OS'!$A$2:$I1000,4,FALSE)) | W36: =IF(ISBLANK(C36),"",UPPER(TEXT(C36,"MMMM"))) | X36: =IF(C36="","",MONTH(C36)) | Y36: =IF(C36="","", YEAR(C36))
B37: =IF(A37="","",VLOOKUP(A37,'BASE OS'!$A$2:$I1000,2,FALSE)) | J37: =H37+I37 -> 0 | M37: =J37-K37-L37 -> 0 | T37: =IF(A37="","",VLOOKUP(A37,'BASE OS'!$A$2:$I1000,4,FALSE)) | W37: =IF(ISBLANK(C37),"",UPPER(TEXT(C37,"MMMM"))) | X37: =IF(C37="","",MONTH(C37)) | Y37: =IF(C37="","", YEAR(C37))
B38: =IF(A38="","",VLOOKUP(A38,'BASE OS'!$A$2:$I1000,2,FALSE)) | J38: =H38+I38 -> 0 | M38: =J38-K38-L38 -> 0 | T38: =IF(A38="","",VLOOKUP(A38,'BASE OS'!$A$2:$I1000,4,FALSE)) | W38: =IF(ISBLANK(C38),"",UPPER(TEXT(C38,"MMMM"))) | X38: =IF(C38="","",MONTH(C38)) | Y38: =IF(C38="","", YEAR(C38))
B39: =IF(A39="","",VLOOKUP(A39,'BASE OS'!$A$2:$I1000,2,FALSE)) | J39: =H39+I39 -> 0 | M39: =J39-K39-L39 -> 0 | T39: =IF(A39="","",VLOOKUP(A39,'BASE OS'!$A$2:$I1000,4,FALSE)) | W39: =IF(ISBLANK(C39),"",UPPER(TEXT(C39,"MMMM"))) | X39: =IF(C39="","",MONTH(C39)) | Y39: =IF(C39="","", YEAR(C39))
B40: =IF(A40="","",VLOOKUP(A40,'BASE OS'!$A$2:$I1000,2,FALSE)) | J40: =H40+I40 -> 0 | M40: =J40-K40-L40 -> 0 | T40: =IF(A40="","",VLOOKUP(A40,'BASE OS'!$A$2:$I1000,4,FALSE)) | W40: =IF(ISBLANK(C40),"",UPPER(TEXT(C40,"MMMM"))) | X40: =IF(C40="","",MONTH(C40)) | Y40: =IF(C40="","", YEAR(C40))
...

Sheet DATOS_COMPARACION
A1: OS | B1: CLIENTE | C1: FECHA | D1: SERVICIOS CXC | E1: SERVICIOS PREVISTO | F1: GASTOS A TERCEROS CXC | G1: GASTOS A TERCEROS PREVISTO | H1: TOTAL CXC | I1: TOTAL PREVISTO | J1: DIFERENCIA SERVICIOS | K1: DIFERENCIA GASTOS A TERCEROS
A2: {=UNIQUE(INDIRECT("CXC!A2:A"&COUNTA(CXC!A:A)))} -> 001-2024 | B2: {=IF(A2="","",VLOOKUP(A2,INDIRECT("CXC!A2:B"&COUNTA(CXC!A:A)),2,FALSE))} -> PANADERIA SINAI | C2: {=IF(A2="","",VLOOKUP(A2,INDIRECT("CXC!A2:C"&COUNTA(CXC!A:A)),3,FALSE))} -> 45608 | D2: {=IF(A2="","",VLOOKUP(A2,INDIRECT("CXC!A2:H"&COUNTA(CXC!A:A)),8,FALSE))} -> 129.95 | E2: {=IFERROR(IF(A2="","",VLOOKUP(A2,INDIRECT("HISTÓRICO COBROS!A3:E"&COUNTA('HISTÓRICO COBROS'!A:A)),5,FALSE)),"")} -> 129.95 | F2: {=IF(A2="","",VLOOKUP(A2,INDIRECT("CXC!A2:I"&COUNTA(CXC!A:A)),9,FALSE))} -> 33.284 | G2: {=IFERROR(IF(A2="","",VLOOKUP(A2,INDIRECT("HISTÓRICO COBROS!A3:F"&COUNTA('HISTÓRICO COBROS'!A:A)),6,FALSE)),"")} -> 33.284 | H2: =IF(D2="","",D2+F2) -> 163.234 | I2: =IF(E2="","",E2+G2) -> 163.234 | J2: =IF(D2="","",D2-E2) -> 0 | K2: =IF(F2="","",F2-G2) -> 0
A3: 002-2024 | B3: {=IF(A3="","",VLOOKUP(A3,INDIRECT("CXC!A2:B"&COUNTA(CXC!A:A)),2,FALSE))} -> PINTO Y COMPANIA | C3: {=IF(A3="","",VLOOKUP(A3,INDIRECT("CXC!A2:C"&COUNTA(CXC!A:A)),3,FALSE))} -> 45608 | D3: {=IF(A3="","",VLOOKUP(A3,INDIRECT("CXC!A2:H"&COUNTA(CXC!A:A)),8,FALSE))} -> 67.8 | E3: {=IFERROR(IF(A3="","",VLOOKUP(A3,INDIRECT("HISTÓRICO COBROS!A3:E"&COUNTA('HISTÓRICO COBROS'!A:A)),5,FALSE)),"")} -> 67.8 | F3: {=IF(A3="","",VLOOKUP(A3,INDIRECT("CXC!A2:I"&COUNTA(CXC!A:A)),9,FALSE))} -> 0 | G3: {=IFERROR(IF(A3="","",VLOOKUP(A3,INDIRECT("HISTÓRICO COBROS!A3:F"&COUNTA('HISTÓRICO COBROS'!A:A)),6,FALSE)),"")} -> 0 | H3: =IF(D3="","",D3+F3) -> 67.8 | I3: =IF(E3="","",E3+G3) -> 67.8 | J3: =IF(D3="","",D3-E3) -> 0 | K3: =IF(F3="","",F3-G3) -> 0
A4: 003-2024 | B4: {=IF(A4="","",VLOOKUP(A4,INDIRECT("CXC!A2:B"&COUNTA(CXC!A:A)),2,FALSE))} -> DIVACO | C4: {=IF(A4="","",VLOOKUP(A4,INDIRECT("CXC!A2:C"&COUNTA(CXC!A:A)),3,FALSE))} -> 45608 | D4: {=IF(A4="","",VLOOKUP(A4,INDIRECT("CXC!A2:H"&COUNTA(CXC!A:A)),8,FALSE))} -> 79.1 | E4: {=IFERROR(IF(A4="","",VLOOKUP(A4,INDIRECT("HISTÓRICO COBROS!A3:E"&COUNTA('HISTÓRICO COBROS'!A:A)),5,FALSE)),"")} -> 79.1 | F4: {=IF(A4="","",VLOOKUP(A4,INDIRECT("CXC!A2:I"&COUNTA(CXC!A:A)),9,FALSE))} -> 0 | G4: {=IFERROR(IF(A4="","",VLOOKUP(A4,INDIRECT("HISTÓRICO COBROS!A3:F"&COUNTA('HISTÓRICO COBROS'!A:A)),6,FALSE)),"")} -> 0 | H4: =IF(D4="","",D4+F4) -> 79.1 | I4: =IF(E4="","",E4+G4) -> 79.1 | J4: =IF(D4="","",D4-E4) -> 0 | K4: =IF(F4="","",F4-G4) -> 0
A5: 004-2024 | B5: {=IF(A5="","",VLOOKUP(A5,INDIRECT("CXC!A2:B"&COUNTA(CXC!A:A)),2,FALSE))} -> DIGICEL | C5: {=IF(A5="","",VLOOKUP(A5,INDIRECT("CXC!A2:C"&COUNTA(CXC!A:A)),3,FALSE))} -> 45609 | D5: {=IF(A5="","",VLOOKUP(A5,INDIRECT("CXC!A2:H"&COUNTA(CXC!A:A)),8,FALSE))} -> 113 | E5: {=IFERROR(IF(A5="","",VLOOKUP(A5,INDIRECT("HISTÓRICO COBROS!A3:E"&COUNTA('HISTÓRICO COBROS'!A:A)),5,FALSE)),"")} -> 113 | F5: {=IF(A5="","",VLOOKUP(A5,INDIRECT("CXC!A2:I"&COUNTA(CXC!A:A)),9,FALSE))} -> 0 | G5: {=IFERROR(IF(A5="","",VLOOKUP(A5,INDIRECT("HISTÓRICO COBROS!A3:F"&COUNTA('HISTÓRICO COBROS'!A:A)),6,FALSE)),"")} -> 0 | H5: =IF(D5="","",D5+F5) -> 113 | I5: =IF(E5="","",E5+G5) -> 113 | J5: =IF(D5="","",D5-E5) -> 0 | K5: =IF(F5="","",F5-G5) -> 0
A6: 005-2024 | B6: {=IF(A6="","",VLOOKUP(A6,INDIRECT("CXC!A2:B"&COUNTA(CXC!A:A)),2,FALSE))} -> AISAL | C6: {=IF(A6="","",VLOOKUP(A6,INDIRECT("CXC!A2:C"&COUNTA(CXC!A:A)),3,FALSE))} -> 45609 | D6: {=IF(A6="","",VLOOKUP(A6,INDIRECT("CXC!A2:H"&COUNTA(CXC!A:A)),8,FALSE))} -> 50.59 | E6: {=IFERROR(IF(A6="","",VLOOKUP(A6,INDIRECT("HISTÓRICO COBROS!A3:E"&COUNTA('HISTÓRICO COBROS'!A:A)),5,FALSE)),"")} | F6: {=IF(A6="","",VLOOKUP(A6,INDIRECT("CXC!A2:I"&COUNTA(CXC!A:A)),9,FALSE))} -> 53.55 | G6: {=IFERROR(IF(A6="","",VLOOKUP(A6,INDIRECT("HISTÓRICO COBROS!A3:F"&COUNTA('HISTÓRICO COBROS'!A:A)),6,FALSE)),"")} | H6: =IF(D6="","",D6+F6) -> 104.14 | I6: =IF(E6="","",E6+G6) | J6: =IF(D6="","",D6-E6) -> 50.59 | K6: =IF(F6="","",F6-G6) -> 53.55
A7: 006-2024 | B7: {=IF(A7="","",VLOOKUP(A7,INDIRECT("CXC!A2:B"&COUNTA(CXC!A:A)),2,FALSE))} -> GEVI | C7: {=IF(A7="","",VLOOKUP(A7,INDIRECT("CXC!A2:C"&COUNTA(CXC!A:A)),3,FALSE))} -> 45609 | D7: {=IF(A7="","",VLOOKUP(A7,INDIRECT("CXC!A2:H"&COUNTA(CXC!A:A)),8,FALSE))} -> 25.1 | E7: {=IFERROR(IF(A7="","",VLOOKUP(A7,INDIRECT("HISTÓRICO COBROS!A3:E"&COUNTA('HISTÓRICO COBROS'!A:A)),5,FALSE)),"")} | F7: {=IF(A7="","",VLOOKUP(A7,INDIRECT("CXC!A2:I"&COUNTA(CXC!A:A)),9,FALSE))} -> 30.55 | G7: {=IFERROR(IF(A7="","",VLOOKUP(A7,INDIRECT("HISTÓRICO COBROS!A3:F"&COUNTA('HISTÓRICO COBROS'!A:A)),6,FALSE)),"")} | H7: =IF(D7="","",D7+F7) -> 55.65 | I7: =IF(E7="","",E7+G7) | J7: =IF(D7="","",D7-E7) -> 25.1 | K7: =IF(F7="","",F7-G7) -> 30.55
A8: 007-2024 | B8: {=IF(A8="","",VLOOKUP(A8,INDIRECT("CXC!A2:B"&COUNTA(CXC!A:A)),2,FALSE))} -> AISAL | C8: {=IF(A8="","",VLOOKUP(A8,INDIRECT("CXC!A2:C"&COUNTA(CXC!A:A)),3,FALSE))} -> 45609 | D8: {=IF(A8="","",VLOOKUP(A8,INDIRECT("CXC!A2:H"&COUNTA(CXC!A:A)),8,FALSE))} -> 50.1 | E8: {=IFERROR(IF(A8="","",VLOOKUP(A8,INDIRECT("HISTÓRICO COBROS!A3:E"&COUNTA('HISTÓRICO COBROS'!A:A)),5,FALSE)),"")} | F8: {=IF(A8="","",VLOOKUP(A8,INDIRECT("CXC!A2:I"&COUNTA(CXC!A:A)),9,FALSE))} -> 0 | G8: {=IFERROR(IF(A8="","",VLOOKUP(A8,INDIRECT("HISTÓRICO COBROS!A3:F"&COUNTA('HISTÓRICO COBROS'!A:A)),6,FALSE)),"")} | H8: =IF(D8="","",D8+F8) -> 50.1 | I8: =IF(E8="","",E8+G8) | J8: =IF(D8="","",D8-E8) -> 50.1 | K8: =IF(F8="","",F8-G8) -> 0
A9: 008-2024 | B9: {=IF(A9="","",VLOOKUP(A9,INDIRECT("CXC!A2:B"&COUNTA(CXC!A:A)),2,FALSE))} -> QUIMICA INDUSTRIAL | C9: {=IF(A9="","",VLOOKUP(A9,INDIRECT("CXC!A2:C"&COUNTA(CXC!A:A)),3,FALSE))} -> 45609 | D9: {=IF(A9="","",VLOOKUP(A9,INDIRECT("CXC!A2:H"&COUNTA(CXC!A:A)),8,FALSE))} -> 209.05 | E9: {=IFERROR(IF(A9="","",VLOOKUP(A9,INDIRECT("HISTÓRICO COBROS!A3:E"&COUNTA('HISTÓRICO COBROS'!A:A)),5,FALSE)),"")} -> 209.05 | F9: {=IF(A9="","",VLOOKUP(A9,INDIRECT("CXC!A2:I"&COUNTA(CXC!A:A)),9,FALSE))} -> 91.67 | G9: {=IFERROR(IF(A9="","",VLOOKUP(A9,INDIRECT("HISTÓRICO COBROS!A3:F"&COUNTA('HISTÓRICO COBROS'!A:A)),6,FALSE)),"")} -> 91.67 | H9: =IF(D9="","",D9+F9) -> 300.72 | I9: =IF(E9="","",E9+G9) -> 300.72 | J9: =IF(D9="","",D9-E9) -> 0 | K9: =IF(F9="","",F9-G9) -> 0
B10: {=IF(A10="","",VLOOKUP(A10,INDIRECT("CXC!A2:B"&COUNTA(CXC!A:A)),2,FALSE))} | C10: {=IF(A10="","",VLOOKUP(A10,INDIRECT("CXC!A2:C"&COUNTA(CXC!A:A)),3,FALSE))} | D10: {=IF(A10="","",VLOOKUP(A10,INDIRECT("CXC!A2:H"&COUNTA(CXC!A:A)),8,FALSE))} | E10: {=IFERROR(IF(A10="","",VLOOKUP(A10,INDIRECT("HISTÓRICO COBROS!A3:E"&COUNTA('HISTÓRICO COBROS'!A:A)),5,FALSE)),"")} | F10: {=IF(A10="","",VLOOKUP(A10,INDIRECT("CXC!A2:I"&COUNTA(CXC!A:A)),9,FALSE))} | G10: {=IFERROR(IF(A10="","",VLOOKUP(A10,INDIRECT("HISTÓRICO COBROS!A3:F"&COUNTA('HISTÓRICO COBROS'!A:A)),6,FALSE)),"")} | H10: =IF(D10="","",D10+F10) | I10: =IF(E10="","",E10+G10) | J10: =IF(D10="","",D10-E10) | K10: =IF(F10="","",F10-G10)
B11: {=IF(A11="","",VLOOKUP(A11,INDIRECT("CXC!A2:B"&COUNTA(CXC!A:A)),2,FALSE))} | C11: {=IF(A11="","",VLOOKUP(A11,INDIRECT("CXC!A2:C"&COUNTA(CXC!A:A)),3,FALSE))} | D11: {=IF(A11="","",VLOOKUP(A11,INDIRECT("CXC!A2:H"&COUNTA(CXC!A:A)),8,FALSE))} | E11: {=IFERROR(IF(A11="","",VLOOKUP(A11,INDIRECT("HISTÓRICO COBROS!A3:E"&COUNTA('HISTÓRICO COBROS'!A:A)),5,FALSE)),"")} | F11: {=IF(A11="","",VLOOKUP(A11,INDIRECT("CXC!A2:I"&COUNTA(CXC!A:A)),9,FALSE))} | G11: {=IFERROR(IF(A11="","",VLOOKUP(A11,INDIRECT("HISTÓRICO COBROS!A3:F"&COUNTA('HISTÓRICO COBROS'!A:A)),6,FALSE)),"")} | H11: =IF(D11="","",D11+F11) | I11: =IF(E11="","",E11+G11) | J11: =IF(D11="","",D11-E11) | K11: =IF(F11="","",F11-G11)
B12: {=IF(A12="","",VLOOKUP(A12,INDIRECT("CXC!A2:B"&COUNTA(CXC!A:A)),2,FALSE))} | C12: {=IF(A12="","",VLOOKUP(A12,INDIRECT("CXC!A2:C"&COUNTA(CXC!A:A)),3,FALSE))} | D12: {=IF(A12="","",VLOOKUP(A12,INDIRECT("CXC!A2:H"&COUNTA(CXC!A:A)),8,FALSE))} | E12: {=IFERROR(IF(A12="","",VLOOKUP(A12,INDIRECT("HISTÓRICO COBROS!A3:E"&COUNTA('HISTÓRICO COBROS'!A:A)),5,FALSE)),"")} | F12: {=IF(A12="","",VLOOKUP(A12,INDIRECT("CXC!A2:I"&COUNTA(CXC!A:A)),9,FALSE))} | G12: {=IFERROR(IF(A12="","",VLOOKUP(A12,INDIRECT("HISTÓRICO COBROS!A3:F"&COUNTA('HISTÓRICO COBROS'!A:A)),6,FALSE)),"")} | H12: =IF(D12="","",D12+F12) | I12: =IF(E12="","",E12+G12) | J12: =IF(D12="","",D12-E12) | K12: =IF(F12="","",F12-G12)
B13: {=IF(A13="","",VLOOKUP(A13,INDIRECT("CXC!A2:B"&COUNTA(CXC!A:A)),2,FALSE))} | C13: {=IF(A13="","",VLOOKUP(A13,INDIRECT("CXC!A2:C"&COUNTA(CXC!A:A)),3,FALSE))} | D13: {=IF(A13="","",VLOOKUP(A13,INDIRECT("CXC!A2:H"&COUNTA(CXC!A:A)),8,FALSE))} | E13: {=IFERROR(IF(A13="","",VLOOKUP(A13,INDIRECT("HISTÓRICO COBROS!A3:E"&COUNTA('HISTÓRICO COBROS'!A:A)),5,FALSE)),"")} | F13: {=IF(A13="","",VLOOKUP(A13,INDIRECT("CXC!A2:I"&COUNTA(CXC!A:A)),9,FALSE))} | G13: {=IFERROR(IF(A13="","",VLOOKUP(A13,INDIRECT("HISTÓRICO COBROS!A3:F"&COUNTA('HISTÓRICO COBROS'!A:A)),6,FALSE)),"")} | H13: =IF(D13="","",D13+F13) | I13: =IF(E13="","",E13+G13) | J13: =IF(D13="","",D13-E13) | K13: =IF(F13="","",F13-G13)
B14: {=IF(A14="","",VLOOKUP(A14,INDIRECT("CXC!A2:B"&COUNTA(CXC!A:A)),2,FALSE))} | C14: {=IF(A14="","",VLOOKUP(A14,INDIRECT("CXC!A2:C"&COUNTA(CXC!A:A)),3,FALSE))} | D14: {=IF(A14="","",VLOOKUP(A14,INDIRECT("CXC!A2:H"&COUNTA(CXC!A:A)),8,FALSE))} | E14: {=IFERROR(IF(A14="","",VLOOKUP(A14,INDIRECT("HISTÓRICO COBROS!A3:E"&COUNTA('HISTÓRICO COBROS'!A:A)),5,FALSE)),"")} | F14: {=IF(A14="","",VLOOKUP(A14,INDIRECT("CXC!A2:I"&COUNTA(CXC!A:A)),9,FALSE))} | G14: {=IFERROR(IF(A14="","",VLOOKUP(A14,INDIRECT("HISTÓRICO COBROS!A3:F"&COUNTA('HISTÓRICO COBROS'!A:A)),6,FALSE)),"")} | H14: =IF(D14="","",D14+F14) | I14: =IF(E14="","",E14+G14) | J14: =IF(D14="","",D14-E14) | K14: =IF(F14="","",F14-G14)
B15: {=IF(A15="","",VLOOKUP(A15,INDIRECT("CXC!A2:B"&COUNTA(CXC!A:A)),2,FALSE))} | C15: {=IF(A15="","",VLOOKUP(A15,INDIRECT("CXC!A2:C"&COUNTA(CXC!A:A)),3,FALSE))} | D15: {=IF(A15="","",VLOOKUP(A15,INDIRECT("CXC!A2:H"&COUNTA(CXC!A:A)),8,FALSE))} | E15: {=IFERROR(IF(A15="","",VLOOKUP(A15,INDIRECT("HISTÓRICO COBROS!A3:E"&COUNTA('HISTÓRICO COBROS'!A:A)),5,FALSE)),"")} | F15: {=IF(A15="","",VLOOKUP(A15,INDIRECT("CXC!A2:I"&COUNTA(CXC!A:A)),9,FALSE))} | G15: {=IFERROR(IF(A15="","",VLOOKUP(A15,INDIRECT("HISTÓRICO COBROS!A3:F"&COUNTA('HISTÓRICO COBROS'!A:A)),6,FALSE)),"")} | H15: =IF(D15="","",D15+F15) | I15: =IF(E15="","",E15+G15) | J15: =IF(D15="","",D15-E15) | K15: =IF(F15="","",F15-G15)
B16: {=IF(A16="","",VLOOKUP(A16,INDIRECT("CXC!A2:B"&COUNTA(CXC!A:A)),2,FALSE))} | C16: {=IF(A16="","",VLOOKUP(A16,INDIRECT("CXC!A2:C"&COUNTA(CXC!A:A)),3,FALSE))} | D16: {=IF(A16="","",VLOOKUP(A16,INDIRECT("CXC!A2:H"&COUNTA(CXC!A:A)),8,FALSE))} | E16: {=IFERROR(IF(A16="","",VLOOKUP(A16,INDIRECT("HISTÓRICO COBROS!A3:E"&COUNTA('HISTÓRICO COBROS'!A:A)),5,FALSE)),"")} | F16: {=IF(A16="","",VLOOKUP(A16,INDIRECT("CXC!A2:I"&COUNTA(CXC!A:A)),9,FALSE))} | G16: {=IFERROR(IF(A16="","",VLOOKUP(A16,INDIRECT("HISTÓRICO COBROS!A3:F"&COUNTA('HISTÓRICO COBROS'!A:A)),6,FALSE)),"")} | H16: =IF(D16="","",D16+F16) | I16: =IF(E16="","",E16+G16) | J16: =IF(D16="","",D16-E16) | K16: =IF(F16="","",F16-G16)
B17: {=IF(A17="","",VLOOKUP(A17,INDIRECT("CXC!A2:B"&COUNTA(CXC!A:A)),2,FALSE))} | C17: {=IF(A17="","",VLOOKUP(A17,INDIRECT("CXC!A2:C"&COUNTA(CXC!A:A)),3,FALSE))} | D17: {=IF(A17="","",VLOOKUP(A17,INDIRECT("CXC!A2:H"&COUNTA(CXC!A:A)),8,FALSE))} | E17: {=IFERROR(IF(A17="","",VLOOKUP(A17,INDIRECT("HISTÓRICO COBROS!A3:E"&COUNTA('HISTÓRICO COBROS'!A:A)),5,FALSE)),"")} | F17: {=IF(A17="","",VLOOKUP(A17,INDIRECT("CXC!A2:I"&COUNTA(CXC!A:A)),9,FALSE))} | G17: {=IFERROR(IF(A17="","",VLOOKUP(A17,INDIRECT("HISTÓRICO COBROS!A3:F"&COUNTA('HISTÓRICO COBROS'!A:A)),6,FALSE)),"")} | H17: =IF(D17="","",D17+F17) | I17: =IF(E17="","",E17+G17) | J17: =IF(D17="","",D17-E17) | K17: =IF(F17="","",F17-G17)
B18: {=IF(A18="","",VLOOKUP(A18,INDIRECT("CXC!A2:B"&COUNTA(CXC!A:A)),2,FALSE))} | C18: {=IF(A18="","",VLOOKUP(A18,INDIRECT("CXC!A2:C"&COUNTA(CXC!A:A)),3,FALSE))} | D18: {=IF(A18="","",VLOOKUP(A18,INDIRECT("CXC!A2:H"&COUNTA(CXC!A:A)),8,FALSE))} | E18: {=IFERROR(IF(A18="","",VLOOKUP(A18,INDIRECT("HISTÓRICO COBROS!A3:E"&COUNTA('HISTÓRICO COBROS'!A:A)),5,FALSE)),"")} | F18: {=IF(A18="","",VLOOKUP(A18,INDIRECT("CXC!A2:I"&COUNTA(CXC!A:A)),9,FALSE))} | G18: {=IFERROR(IF(A18="","",VLOOKUP(A18,INDIRECT("HISTÓRICO COBROS!A3:F"&COUNTA('HISTÓRICO COBROS'!A:A)),6,FALSE)),"")} | H18: =IF(D18="","",D18+F18) | I18: =IF(E18="","",E18+G18) | J18: =IF(D18="","",D18-E18) | K18: =IF(F18="","",F18-G18)
B19: {=IF(A19="","",VLOOKUP(A19,INDIRECT("CXC!A2:B"&COUNTA(CXC!A:A)),2,FALSE))} | C19: {=IF(A19="","",VLOOKUP(A19,INDIRECT("CXC!A2:C"&COUNTA(CXC!A:A)),3,FALSE))} | D19: {=IF(A19="","",VLOOKUP(A19,INDIRECT("CXC!A2:H"&COUNTA(CXC!A:A)),8,FALSE))} | E19: {=IFERROR(IF(A19="","",VLOOKUP(A19,INDIRECT("HISTÓRICO COBROS!A3:E"&COUNTA('HISTÓRICO COBROS'!A:A)),5,FALSE)),"")} | F19: {=IF(A19="","",VLOOKUP(A19,INDIRECT("CXC!A2:I"&COUNTA(CXC!A:A)),9,FALSE))} | G19: {=IFERROR(IF(A19="","",VLOOKUP(A19,INDIRECT("HISTÓRICO COBROS!A3:F"&COUNTA('HISTÓRICO COBROS'!A:A)),6,FALSE)),"")} | H19: =IF(D19="","",D19+F19) | I19: =IF(E19="","",E19+G19) | J19: =IF(D19="","",D19-E19) | K19: =IF(F19="","",F19-G19)
B20: {=IF(A20="","",VLOOKUP(A20,INDIRECT("CXC!A2:B"&COUNTA(CXC!A:A)),2,FALSE))} | C20: {=IF(A20="","",VLOOKUP(A20,INDIRECT("CXC!A2:C"&COUNTA(CXC!A:A)),3,FALSE))} | D20: {=IF(A20="","",VLOOKUP(A20,INDIRECT("CXC!A2:H"&COUNTA(CXC!A:A)),8,FALSE))} | E20: {=IFERROR(IF(A20="","",VLOOKUP(A20,INDIRECT("HISTÓRICO COBROS!A3:E"&COUNTA('HISTÓRICO COBROS'!A:A)),5,FALSE)),"")} | F20: {=IF(A20="","",VLOOKUP(A20,INDIRECT("CXC!A2:I"&COUNTA(CXC!A:A)),9,FALSE))} | G20: {=IFERROR(IF(A20="","",VLOOKUP(A20,INDIRECT("HISTÓRICO COBROS!A3:F"&COUNTA('HISTÓRICO COBROS'!A:A)),6,FALSE)),"")} | H20: =IF(D20="","",D20+F20) | I20: =IF(E20="","",E20+G20) | J20: =IF(D20="","",D20-E20) | K20: =IF(F20="","",F20-G20)
B21: {=IF(A21="","",VLOOKUP(A21,INDIRECT("CXC!A2:B"&COUNTA(CXC!A:A)),2,FALSE))} | C21: {=IF(A21="","",VLOOKUP(A21,INDIRECT("CXC!A2:C"&COUNTA(CXC!A:A)),3,FALSE))} | D21: {=IF(A21="","",VLOOKUP(A21,INDIRECT("CXC!A2:H"&COUNTA(CXC!A:A)),8,FALSE))} | E21: {=IFERROR(IF(A21="","",VLOOKUP(A21,INDIRECT("HISTÓRICO COBROS!A3:E"&COUNTA('HISTÓRICO COBROS'!A:A)),5,FALSE)),"")} | F21: {=IF(A21="","",VLOOKUP(A21,INDIRECT("CXC!A2:I"&COUNTA(CXC!A:A)),9,FALSE))} | G21: {=IFERROR(IF(A21="","",VLOOKUP(A21,INDIRECT("HISTÓRICO COBROS!A3:F"&COUNTA('HISTÓRICO COBROS'!A:A)),6,FALSE)),"")} | H21: =IF(D21="","",D21+F21) | I21: =IF(E21="","",E21+G21) | J21: =IF(D21="","",D21-E21) | K21: =IF(F21="","",F21-G21)
... B1000: {=IF(A1000="","",VLOOKUP(A1000,INDIRECT("CXC!A2:B"&COUNTA(CXC!A:A)),2,FALSE))} | C1000: {=IF(A1000="","",VLOOKUP(A1000,INDIRECT("CXC!A2:C"&COUNTA(CXC!A:A)),3,FALSE))} | D1000: {=IF(A1000="","",VLOOKUP(A1000,INDIRECT("CXC!A2:H"&COUNTA(CXC!A:A)),8,FALSE))} | E1000: {=IFERROR(IF(A1000="","",VLOOKUP(A1000,INDIRECT("HISTÓRICO COBROS!A3:E"&COUNTA('HISTÓRICO COBROS'!A:A)),5,FALSE)),"")} | F1000: {=IF(A1000="","",VLOOKUP(A1000,INDIRECT("CXC!A2:I"&COUNTA(CXC!A:A)),9,FALSE))} | G1000: {=IFERROR(IF(A1000="","",VLOOKUP(A1000,INDIRECT("HISTÓRICO COBROS!A3:F"&COUNTA('HISTÓRICO COBROS'!A:A)),6,FALSE)),"")} | H1000: =IF(D1000="","",D1000+F1000) | I1000: =IF(E1000="","",E1000+G1000) | J1000: =IF(D1000="","",D1000-E1000) | K1000: =IF(F1000="","",F1000-G1000)

Sheet BUSQUEDAS
A1: BÚSQUEDA PERSONALIZADA
A3: Buscar Por OS | B3: 001-2024
A5: =IFERROR(__xludf.DUMMYFUNCTION("QUERY('BASE TRANSFERENCIAS'!A:K,""select * where A contains '""&B3&""' or B contains '""&B3&""'"",1)"),"OS") -> OS | B5: =IFERROR(__xludf.DUMMYFUNCTION("""COMPUTED_VALUE"""),"CLIENTE") -> CLIENTE | C5: =IFERROR(__xludf.DUMMYFUNCTION("""COMPUTED_VALUE"""),"SUB CLIENTE") -> SUB CLIENTE | D5: =IFERROR(__xludf.DUMMYFUNCTION("""COMPUTED_VALUE"""),"A NOMBRE DE") -> A NOMBRE DE | E5: =IFERROR(__xludf.DUMMYFUNCTION("""COMPUTED_VALUE"""),"DETALLE") -> DETALLE | F5: =IFERROR(__xludf.DUMMYFUNCTION("""COMPUTED_VALUE"""),"CCF") -> CCF | G5: =IFERROR(__xludf.DUMMYFUNCTION("""COMPUTED_VALUE"""),"MONTO") -> MONTO | H5: =IFERROR(__xludf.DUMMYFUNCTION("""COMPUTED_VALUE"""),"SOLICITADO POR") -> SOLICITADO POR | I5: =IFERROR(__xludf.DUMMYFUNCTION("""COMPUTED_VALUE"""),"BANCO") -> BANCO | J5: =IFERROR(__xludf.DUMMYFUNCTION("""COMPUTED_VALUE"""),"TIPO") -> TIPO | K5: =IFERROR(__xludf.DUMMYFUNCTION("""COMPUTED_VALUE"""),"FECHA") -> FECHA
A6: =IFERROR(__xludf.DUMMYFUNCTION("""COMPUTED_VALUE"""),"001-2024") -> 001-2024 | B6: =IFERROR(__xludf.DUMMYFUNCTION("""COMPUTED_VALUE"""),"PANADERIA SINAI") -> PANADERIA SINAI | C6: =IFERROR(__xludf.DUMMYFUNCTION("""COMPUTED_VALUE"""),"N/A") -> N/A | D6: =IFERROR(__xludf.DUMMYFUNCTION("""COMPUTED_VALUE"""),"M.H") -> M.H | E6: =IFERROR(__xludf.DUMMYFUNCTION("""COMPUTED_VALUE"""),"IMPUESTOS") -> IMPUESTOS | G6: =IFERROR(__xludf.DUMMYFUNCTION("""COMPUTED_VALUE"""),33.284) -> 33.284 | H6: =IFERROR(__xludf.DUMMYFUNCTION("""COMPUTED_VALUE"""),"MARÍA JOSE") -> MARÍA JOSE | I6: =IFERROR(__xludf.DUMMYFUNCTION("""COMPUTED_VALUE"""),"AGRICOLA") -> AGRICOLA | J6: =IFERROR(__xludf.DUMMYFUNCTION("""COMPUTED_VALUE"""),"CARGOS A CLIENTES") -> CARGOS A CLIENTES | K6: =IFERROR(__xludf.DUMMYFUNCTION("""COMPUTED_VALUE"""),45606.0) -> 45606

Sheet LISTAS
A1: Aforadores | B1: Clientes | C1: Bancos | D1: Tipo de Gasto | E1: OS | F1: Tipo de Factura | G1: Tipo de Pago
A2: ADELAYDA | B2: EFL | C2: AGRICOLA | D2: CARGOS A CLIENTES | E2: =IFERROR(__xludf.DUMMYFUNCTION("ARRAYFORMULA({""ADMON""; FILTER(ListaOS, LEN(ListaOS) > 0)}) "),"ADMON") -> ADMON | F2: DTE | G2: TRANSFERENCIA
A3: GLENDA CAÑAS | B3: SERTAGRI | C3: DAVIVIENDA | D3: COSTO | E3: =IFERROR(__xludf.DUMMYFUNCTION("""COMPUTED_VALUE"""),"001-2024") -> 001-2024 | F3: FEX | G3: EFECTIVO
A4: MARÍA JOSE | B4: PANADERIA SINAI | C4: CHEQUE | D4: GASTOS DE OPERACIÓN | E4: =IFERROR(__xludf.DUMMYFUNCTION("""COMPUTED_VALUE"""),"002-2024") -> 002-2024 | G4: CHEQUE
A5: ROBERTO | B5: DIGICEL | E5: =IFERROR(__xludf.DUMMYFUNCTION("""COMPUTED_VALUE"""),"003-2024") -> 003-2024
B6: DIVACO | E6: =IFERROR(__xludf.DUMMYFUNCTION("""COMPUTED_VALUE"""),"004-2024") -> 004-2024
B7: TRANSTAINER | E7: =IFERROR(__xludf.DUMMYFUNCTION("""COMPUTED_VALUE"""),"005-2024") -> 005-2024
B8: FERRETERIA TIO WILLIS | E8: =IFERROR(__xludf.DUMMYFUNCTION("""COMPUTED_VALUE"""),"006-2024") -> 006-2024
B9: DANIEL MONTERROZA | E9: =IFERROR(__xludf.DUMMYFUNCTION("""COMPUTED_VALUE"""),"007-2024") -> 007-2024
B10: PINTO Y COMPANIA | E10: =IFERROR(__xludf.DUMMYFUNCTION("""COMPUTED_VALUE"""),"008-2024") -> 008-2024
B11: GEVI
B12: SERTAGRI
B13: HAROLD CALDERON
B14: PINTO Y COMPAÑIA
B15: MEDICALD
B16: IMPORTADORA MILKY
B17: ALIMENTOS MADRE TIERRA
B18: TRANSTAINER
B19: AISAL
B20: QUIMICA INDUSTRIAL
B21: SOLVI
B22: AVICOLA
B23: POLLO CAMPESTRE

Sheet DATOS_GRAFICO
A1: =IFERROR(__xludf.DUMMYFUNCTION("QUERY( 'BASE OS'!A:H, ""SELECT E, COUNT(A) GROUP BY E ORDER BY COUNT(A) DESC LIMIT 4"", 0 )"),"") | B1: =IFERROR(__xludf.DUMMYFUNCTION("""COMPUTED_VALUE"""),"count ") -> count
A2: =IFERROR(__xludf.DUMMYFUNCTION("""COMPUTED_VALUE"""),"ADELAYDA") -> ADELAYDA | B2: =IFERROR(__xludf.DUMMYFUNCTION("""COMPUTED_VALUE"""),2.0) -> 2
A3: =IFERROR(__xludf.DUMMYFUNCTION("""COMPUTED_VALUE"""),"GLENDA CAÑAS") -> GLENDA CAÑAS | B3: =IFERROR(__xludf.DUMMYFUNCTION("""COMPUTED_VALUE"""),2.0) -> 2
A4: =IFERROR(__xludf.DUMMYFUNCTION("""COMPUTED_VALUE"""),"MARÍA JOSE") -> MARÍA JOSE | B4: =IFERROR(__xludf.DUMMYFUNCTION("""COMPUTED_VALUE"""),2.0) -> 2
A5: =IFERROR(__xludf.DUMMYFUNCTION("""COMPUTED_VALUE"""),"ROBERTO") -> ROBERTO | B5: =IFERROR(__xludf.DUMMYFUNCTION("""COMPUTED_VALUE"""),2.0) -> 2

Sheet TARIFARIO
A1: CODIGO | B1: CLIENTE | C1: SERVICIO | D1: MONTO SIN IVA | F1: SERVICIOS PARA OTROS CLIENTES | I1: LISTA DE SERVICIOS POR CLIENTE SELECCIONADO
A2: AISAL | B2: ALIMENTO IMPORTADOS SUPERIORES DE EL SALVADOR, S.A DE C.V | C2: ASESORIA Y GESTION ADUANERA | D2: 90 | F2: SERVICIO | G2: PRECIO | I2: =IFERROR(__xludf.DUMMYFUNCTION("IF(COUNTIF(A2:A1000, 'CALCULO COBROS'!D4) > 0, {FILTER(C:D, A:A = 'CALCULO COBROS'!D4); F3:G1000}, ARRAYFORMULA(F3:G100) )"),"")
A3: AISAL | B3: ALIMENTO IMPORTADOS SUPERIORES DE EL SALVADOR, S.A DE C.V | C3: ASESORIA Y GESTION ADUANERA GT | D3: 45 | F3: ASESORÍA Y GESTIÓN ADUANAL - OTRO | G3: 0
A4: AISAL | B4: ALIMENTO IMPORTADOS SUPERIORES DE EL SALVADOR, S.A DE C.V | C4: GESTION DE PERMISO DE SALUD | D4: 25 | F4: DECLARACIÓN ESCALONADA - OTRO | G4: 0
A5: AISAL | B5: ALIMENTO IMPORTADOS SUPERIORES DE EL SALVADOR, S.A DE C.V | C5: SERVICIO POR TIEMPO EXTRAORDINARIO | D5: 25 | F5: ELABORACIÓN DUCA T - OTRO | G5: 0
A6: AISAL | B6: ALIMENTO IMPORTADOS SUPERIORES DE EL SALVADOR, S.A DE C.V | C6: GESTION POR SELECTIVO ROJO | D6: 25 | F6: GESTIÓN DE PERMISO DE SALUD - OTRO | G6: 0
A7: AISAL | B7: ALIMENTO IMPORTADOS SUPERIORES DE EL SALVADOR, S.A DE C.V | C7: SERVICIO DE CUADRILLA SAN CRISTOBAL | D7: 150 | F7: GESTIÓN POR MULTA - OTRO | G7: 0
A8: AISAL | B8: ALIMENTO IMPORTADOS SUPERIORES DE EL SALVADOR, S.A DE C.V | C8: REGISTRO SANITARIO POR PRODUCTO | D8: 100 | F8: GESTIÓN POR SELECTIVO ROJO - OTRO | G8: 0
A9: AISAL | B9: ALIMENTO IMPORTADOS SUPERIORES DE EL SALVADOR, S.A DE C.V | C9: TRANSPORTE LOCAL CLG (OFI BODEGA) | D9: 130 | F9: GESTIÓN REVISIÓN DAN - OTRO | G9: 0
A10: ADVANCE | B10: ADVANCE BS EL SALVADOR, S.A DE C.V | C10: ASESORIA Y GESTION ADUANERA | D10: 90 | F10: REGISTRO SANITARIO POR PRODUCTO - OTRO | G10: 0
A11: ADVANCE | B11: ADVANCE BS EL SALVADOR, S.A DE C.V | C11: GESTION DE PERMISO DE SALUD | D11: 25 | F11: SERVICIO DE CUADRILLA - OTRO | G11: 0
A12: ADIMACON | B12: ADIMACON, S.A DE C.V | C12: ASESORIA Y GESTION ADUANERA AMATILLO SV | D12: 95 | F12: TRANSPORTE LOCAL - OTRO | G12: 0
A13: ADIMACON | B13: ADIMACON, S.A DE C.V | C13: ASESORIA Y GESTION ADUANERA AMATILLO HN | D13: 25
A14: ADIMACON | B14: ADIMACON, S.A DE C.V | C14: ASESORIA Y GESTION ADUANERA ACAJUTLA | D14: 80
A15: ADIMACON | B15: ADIMACON, S.A DE C.V | C15: GESTION REVISION DAN | D15: 20
A16: ADIMACON | B16: ADIMACON, S.A DE C.V | C16: GESTION POR SELECTIVO ROJO | D16: 25
A17: ENERLAND | B17: ENERLAND GROUP EL SALVADOR, S.A DE C.V | C17: TRANSPORTE LOCAL INGENIO JIBOA | D17: 465
A18: ENERLAND | B18: ENERLAND GROUP EL SALVADOR, S.A DE C.V | C18: TRANSPORTE LOCAL SOLAR INTERNACIONAL | D18: 295
A19: ENERLAND | B19: ENERLAND GROUP EL SALVADOR, S.A DE C.V | C19: SELECTIVO ROJO | D19: 35
A20: ENERLAND | B20: ENERLAND GROUP EL SALVADOR, S.A DE C.V | C20: MOVIMIENTO POR ESCALONADO | D20: 110
A21: ENERLAND | B21: ENERLAND GROUP EL SALVADOR, S.A DE C.V | C21: DECLARACION ESCALONADA | D21: 180
A22: ENERLAND | B22: ENERLAND GROUP EL SALVADOR, S.A DE C.V | C22: ESTADIA | D22: 50
A23: ENERLAND | B23: ENERLAND GROUP EL SALVADOR, S.A DE C.V | C23: ASESORIA Y GESTION ADUANERA | D23: 85
A24: ENERLAND | B24: ENERLAND GROUP EL SALVADOR, S.A DE C.V | C24: PRESENTACION DE ESCRITO POR AGRUPACION DE BL | D24: 50
... A120: AVICOLA | B120: AVICOLA CAMPESTRE, S.A DE C.V | C120: TRANSPOTR LOCAL EQUIPO DE 8 TONELADAS | D120: 260
I882: =IFERROR(__xludf.DUMMYFUNCTION("""COMPUTED_VALUE"""),"ASESORÍA Y GESTIÓN ADUANAL - OTRO") -> ASESORÍA Y GESTIÓN ADUANAL - OTRO | J882: =IFERROR(__xludf.DUMMYFUNCTION("""COMPUTED_VALUE"""),0.0) -> 0
I883: =IFERROR(__xludf.DUMMYFUNCTION("""COMPUTED_VALUE"""),"DECLARACIÓN ESCALONADA - OTRO") -> DECLARACIÓN ESCALONADA - OTRO | J883: =IFERROR(__xludf.DUMMYFUNCTION("""COMPUTED_VALUE"""),0.0) -> 0
I884: =IFERROR(__xludf.DUMMYFUNCTION("""COMPUTED_VALUE"""),"ELABORACIÓN DUCA T - OTRO") -> ELABORACIÓN DUCA T - OTRO | J884: =IFERROR(__xludf.DUMMYFUNCTION("""COMPUTED_VALUE"""),0.0) -> 0
I885: =IFERROR(__xludf.DUMMYFUNCTION("""COMPUTED_VALUE"""),"GESTIÓN DE PERMISO DE SALUD - OTRO") -> GESTIÓN DE PERMISO DE SALUD - OTRO | J885: =IFERROR(__xludf.DUMMYFUNCTION("""COMPUTED_VALUE"""),0.0) -> 0
I886: =IFERROR(__xludf.DUMMYFUNCTION("""COMPUTED_VALUE"""),"GESTIÓN POR MULTA - OTRO") -> GESTIÓN POR MULTA - OTRO | J886: =IFERROR(__xludf.DUMMYFUNCTION("""COMPUTED_VALUE"""),0.0) -> 0
I887: =IFERROR(__xludf.DUMMYFUNCTION("""COMPUTED_VALUE"""),"GESTIÓN POR SELECTIVO ROJO - OTRO") -> GESTIÓN POR SELECTIVO ROJO - OTRO | J887: =IFERROR(__xludf.DUMMYFUNCTION("""COMPUTED_VALUE"""),0.0) -> 0
I888: =IFERROR(__xludf.DUMMYFUNCTION("""COMPUTED_VALUE"""),"GESTIÓN REVISIÓN DAN - OTRO") -> GESTIÓN REVISIÓN DAN - OTRO | J888: =IFERROR(__xludf.DUMMYFUNCTION("""COMPUTED_VALUE"""),0.0) -> 0
I889: =IFERROR(__xludf.DUMMYFUNCTION("""COMPUTED_VALUE"""),"REGISTRO SANITARIO POR PRODUCTO - OTRO") -> REGISTRO SANITARIO POR PRODUCTO - OTRO | J889: =IFERROR(__xludf.DUMMYFUNCTION("""COMPUTED_VALUE"""),0.0) -> 0
I890: =IFERROR(__xludf.DUMMYFUNCTION("""COMPUTED_VALUE"""),"SERVICIO DE CUADRILLA - OTRO") -> SERVICIO DE CUADRILLA - OTRO | J890: =IFERROR(__xludf.DUMMYFUNCTION("""COMPUTED_VALUE"""),0.0) -> 0
I891: =IFERROR(__xludf.DUMMYFUNCTION("""COMPUTED_VALUE"""),"TRANSPORTE LOCAL - OTRO") -> TRANSPORTE LOCAL - OTRO | J891: =IFERROR(__xludf.DUMMYFUNCTION("""COMPUTED_VALUE"""),0.0) -> 0
